File: Co0.5Ni0.5TiO3 data/Co0.5Ni0.5TiO3 Magnetic Suceptibility data/CNTO_1000C_24h_newsampleagain_kai_vs_T_DC_300K_00001.raw
[Header]
; ACMS II Raw Data File (default extension .raw)
; Copyright 2014, Quantum Design, Inc. All rights reserved.
TITLE,
FILEOPENTIME,3955995606.120,05/09/2025,11:40 pm
BYAPP,ACMS II,1.0,1.2
INFO,PPMS ACMS II Option Release 1.0.8 Build 47,APPNAME
INFO,WF236,COIL_SERIAL_NUMBER
INFO,0,MOMENT_UNITS
INFO,CoNiTiO3,SAMPLE_MATERIAL
INFO,,SAMPLE_COMMENT
INFO,,SAMPLE_MASS
INFO,,SAMPLE_VOLUME
INFO,,SAMPLE_MOLECULAR_WEIGHT
INFO,,SAMPLE_SIZE
INFO,,SAMPLE_SHAPE
DATATYPE,COMMENT,1
DATATYPE,TIME,2
STARTUPAXIS,X,2
STARTUPAXIS,Y1,3
[Data]
Comment,Time (sec),Measure No.,Measure Type,Point Type,Temperature (K),Field (Oe),Drive (Oe or mm),Frequency (Hz),Gain,Position (mm),Ch1_inPhase (V),Ch1_quadrature (V),Ch2_inPhase (V),Ch2_quadrature (V),Trim ratio,Trim phase (deg),Null Status,Ch1_maxSignal (V),Ch2_maxSignal (V)
,3955995606.08063,0,2,0,300.00116,0.268252849578857,2,39.995735168457,10,21.9999998807907,-2.5976483186696E-009,1.34195774492696E-008,-1.95514185179491E-005,-5.5488867474196E-006,0,0,0,0.0406153909862041,0.897864520549774,61440,0,0,0,0,0,0,0,0,0,0,0,0,0,0,0,0,0,0
,3955995735.65514,0,2,0,299.9517515,0.268252849578857,2,39.995735168457,10,21.9999998807907,-6.14870003801116E-008,-2.30396167921754E-007,-9.19002650334733E-006,-2.39657110796543E-005,0,0,0,0.0387957654893398,1.09270167350769,61520,0,0,0,0,0,0,0,0,0,0,0,0,0,0,0,0,0,0
,3955995863.2079,0,2,0,299.137451,0.268252849578857,2,39.995735168457,10,21.9999998807907,-4.78478376919611E-008,1.05794335070186E-007,1.28473320728517E-005,-1.99325986613985E-005,0,0,0,0.0518421307206154,1.10282981395721,61520,0,0,0,0,0,0,0,0,0,0,0,0,0,0,0,0,0,0
,3955995987.53333,0,2,0,296.1309815,0.268252849578857,2,39.995735168457,10,21.9999998807907,-1.98797849293442E-007,3.81306319852115E-009,2.35135121329222E-005,-3.27001680489047E-006,0,0,0,0.0327875725924969,1.12432193756104,59280,0,0,0,0,0,0,0,0,0,0,0,0,0,0,0,0,0,0
,3955996108.16072,0,2,0,290.7378995,0.268252849578857,2,39.995735168457,10,21.9999998807907,-1.37605226768756E-007,-3.16390149635026E-008,1.83083884621738E-005,1.42054177558748E-005,0,0,0,0.0450442880392075,0.979884922504425,59280,0,0,0,0,0,0,0,0,0,0,0,0,0,0,0,0,0,0
,3955996228.55861,0,2,0,283.166626,0.268252849578857,2,39.995735168457,10,21.9999998807907,2.15835189720792E-008,-2.05100405992198E-007,1.99639839593146E-006,2.41151028603781E-005,0,0,0,0.0307619534432888,1.09445261955261,59280,0,0,0,0,0,0,0,0,0,0,0,0,0,0,0,0,0,0
,3955996349.83895,0,2,0,273.881775,0.268252849578857,2,39.995735168457,10,21.9999998807907,-7.53088400529123E-008,2.26216045895455E-009,-1.54894805746153E-005,1.62387659656815E-005,0,0,0,0.0569233484566212,0.874724388122559,61440,0,0,0,0,0,0,0,0,0,0,0,0,0,0,0,0,0,0
,3955996472.14275,0,2,0,263.25795,0.268252849578857,2,39.995735168457,10,21.9999998807907,2.42043682874282E-008,-3.28642428826242E-008,-2.2536989490618E-005,-1.51243270352097E-007,0,0,0,0.0358088351786137,0.897040545940399,59280,0,0,0,0,0,0,0,0,0,0,0,0,0,0,0,0,0,0
,3955996599.08616,0,2,0,251.523697,0.268252849578857,2,39.995735168457,10,21.9999998807907,-6.29142036245867E-008,6.01594010163353E-008,-1.36302205646643E-005,-1.55703728523804E-005,0,0,0,0.0396884121000767,0.883994162082672,61520,0,0,0,0,0,0,0,0,0,0,0,0,0,0,0,0,0,0
,3955996719.01658,0,2,0,240.101051,0.268252849578857,2,39.995735168457,10,21.9999998807907,-5.7070629111422E-008,2.69886072601366E-007,3.84831491828663E-006,-1.84529235411901E-005,0,0,0,0.0461085960268974,0.980537295341492,61520,0,0,0,0,0,0,0,0,0,0,0,0,0,0,0,0,0,0
,3955996844.8805,0,2,0,227.9311525,0.268252849578857,2,39.995735168457,10,21.9999998807907,5.97107373323524E-007,6.19098670995299E-007,1.97381741600111E-005,-8.78425726114074E-006,0,0,0,0.0432246662676334,1.04377782344818,61440,0,0,0,0,0,0,0,0,0,0,0,0,0,0,0,0,0,0
,3955996968.59876,0,2,0,216.023758,0.268252849578857,2,39.995735168457,10,21.9999998807907,9.89207560309069E-009,-5.35046865479671E-007,2.19079083763063E-005,8.08735785540193E-006,0,0,0,0.0512241460382938,0.862639307975769,61520,0,0,0,0,0,0,0,0,0,0,0,0,0,0,0,0,0,0
,3955997095.24182,0,2,0,203.956856,0.268252849578857,2,39.995735168457,10,21.9999998807907,1.0070406375462E-007,-3.64212020542709E-008,5.71048985875677E-006,2.04985772143118E-005,0,0,0,0.0384524427354336,0.943080484867096,61520,0,0,0,0,0,0,0,0,0,0,0,0,0,0,0,0,0,0
,3955997217.6511,0,2,0,192.440628,0.268252849578857,2,39.995735168457,10,21.9999998807907,-1.52515127638253E-007,-1.38159101936708E-008,-1.03785405372037E-005,1.83076390385395E-005,0,0,0,0.0413363762199879,0.865282952785492,59280,0,0,0,0,0,0,0,0,0,0,0,0,0,0,0,0,0,0
,3955997338.36935,0,2,0,181.490486,0.268252849578857,2,39.995735168457,10,21.9999998807907,3.23335541452252E-007,5.92306321323122E-007,-1.95631255337503E-005,3.2369689506595E-006,0,0,0,0.0456966087222099,0.877264976501465,61520,0,0,0,0,0,0,0,0,0,0,0,0,0,0,0,0,0,0
,3955997462.52479,0,2,0,170.442909,0.268252849578857,2,39.995735168457,10,21.9999998807907,1.07020035500227E-007,-1.99987027826865E-007,-1.68467813637108E-005,-1.07326104625827E-005,0,0,0,0.0297319777309895,0.854433834552765,61440,0,0,0,0,0,0,0,0,0,0,0,0,0,0,0,0,0,0
,3955997636.51625,0,2,0,155.7767945,0.268252849578857,2,39.995735168457,10,21.9999998807907,-1.1793497378676E-007,7.79571163178616E-009,4.52069207312888E-006,-1.551252171339E-005,0,0,0,0.0346071980893612,0.885333120822906,61520,0,0,0,0,0,0,0,0,0,0,0,0,0,0,0,0,0,0
,3955997786.27898,0,2,0,143.5918195,0.268252849578857,2,39.995735168457,10,21.9999998807907,1.39750696348528E-007,-4.3440476105161E-008,1.63927252287976E-005,-2.74706485470233E-006,0,0,0,0.0616955682635307,0.974323093891144,59280,0,0,0,0,0,0,0,0,0,0,0,0,0,0,0,0,0,0
,3955997889.96847,0,2,0,135.5173565,0.268252849578857,2,39.995735168457,10,21.9999998807907,1.18313970176587E-007,1.83275304266317E-007,1.28297187984572E-005,9.37604363571154E-006,0,0,0,0.0464175902307034,1.0404132604599,61440,0,0,0,0,0,0,0,0,0,0,0,0,0,0,0,0,0,0
,3955997997.59857,0,2,0,127.39225,0.268252849578857,2,39.995735168457,10,21.9999998807907,7.23978743621956E-008,-9.85153931765126E-008,4.0415156945528E-006,1.59452083607903E-005,0,0,0,0.0336802192032337,0.856699824333191,61520,0,0,0,0,0,0,0,0,0,0,0,0,0,0,0,0,0,0
,3955998094.24414,0,2,0,120.2191125,0.268252849578857,2,39.995735168457,10,21.9999998807907,-8.62238707100005E-008,5.41168496681621E-008,-6.42523218630231E-006,1.38081413751934E-005,0,0,0,0.0634121969342232,0.94167286157608,61520,0,0,0,0,0,0,0,0,0,0,0,0,0,0,0,0,0,0
,3955998192.28601,0,2,0,112.8517725,0.268252849578857,2,39.995735168457,10,21.9999998807907,7.73307391455091E-008,-2.16809198150258E-007,-1.35783611767692E-005,8.39488166093361E-006,0,0,0,0.0381777808070183,0.920352339744568,59280,0,0,0,0,0,0,0,0,0,0,0,0,0,0,0,0,0,0
,3955998299.94373,0,2,0,100.3667295,0.268252849578857,2,39.995735168457,10,21.9999998807907,4.28464055346467E-008,1.42718434403832E-007,-1.48007338793832E-005,-3.736596681847E-006,0,0,0,0.0369761437177658,1.24761009216309,61520,0,0,0,0,0,0,0,0,0,0,0,0,0,0,0,0,0,0
,3955998412.0869,0,2,0,83.515736,0.268252849578857,2,39.995735168457,10,21.9999998807907,1.52601316472101E-007,-4.74412047424266E-008,-7.67501387599623E-006,-1.13094765765709E-005,0,0,0,0.0570950098335743,1.01641476154327,61440,0,0,0,0,0,0,0,0,0,0,0,0,0,0,0,0,0,0
,3955998515.1923,0,2,0,67.042301,0.268252849578857,2,39.995735168457,10,21.9999998807907,7.04851430555209E-008,4.59721718470973E-008,2.32558727475407E-006,-1.22246883620392E-005,0,0,0,0.0413020439445972,0.938857555389404,61440,0,0,0,0,0,0,0,0,0,0,0,0,0,0,0,0,0,0
,3955998607.14613,0,2,0,53.057003,0.268252849578857,2,39.995735168457,10,21.9999998807907,5.76910785810014E-009,1.03243593230218E-007,1.09468037408078E-005,-8.69804443937028E-006,0,0,0,0.0463832579553127,1.00117111206055,59280,0,0,0,0,0,0,0,0,0,0,0,0,0,0,0,0,0,0
,3955998693.26278,0,2,0,39.55188,0.268252849578857,2,39.995735168457,10,21.9999998807907,1.65017567610448E-007,-4.47445174245331E-008,1.5617875760654E-005,-9.4203858225228E-007,0,0,0,0.0395854152739048,0.987850069999695,61520,0,0,0,0,0,0,0,0,0,0,0,0,0,0,0,0,0,0
,3955998772.57168,0,2,0,22.0853725,0.268252849578857,2,39.995735168457,10,21.9999998807907,3.84599474045899E-007,1.01103765359767E-007,1.50963869600673E-005,9.72765155893285E-006,0,0,0,0.0324099138379097,0.85663115978241,61440,0,0,0,0,0,0,0,0,0,0,0,0,0,0,0,0,0,0
,3955998863.92068,0,2,0,9.607446,0.268252849578857,2,39.995735168457,10,21.9999998807907,5.48042464743048E-008,-1.56515955751502E-008,6.34626530882088E-006,1.42367989610648E-005,0,0,0,0.060219269245863,0.927699506282806,59280,0,0,0,0,0,0,0,0,0,0,0,0,0,0,0,0,0,0
,3955998962.96761,0,2,0,9.0746025,0.268252849578857,2,39.995735168457,10,21.9999998807907,-6.69128326080681E-008,3.73466342296069E-008,-3.31127944264153E-006,1.14331014628988E-005,0,0,0,0.0323412492871284,0.849283993244171,59280,0,0,0,0,0,0,0,0,0,0,0,0,0,0,0,0,0,0
,3955999059.56856,0,2,0,8.8012955,0.268252849578857,2,39.995735168457,10,21.9999998807907,-6.91290793497501E-008,-4.37833902466878E-009,-9.08437596081058E-006,7.90568174124928E-006,0,0,0,0.0383837781846523,0.932712018489838,59280,0,0,0,0,0,0,0,0,0,0,0,0,0,0,0,0,0,0
,3955999156.366,0,2,0,8.4767095,0.268252849578857,2,39.995735168457,10,21.9999998807907,3.18949446409533E-007,-3.62437276635319E-007,-1.37621609610505E-005,1.86739157470583E-006,0,0,0,0.0368044786155224,0.884028494358063,61520,0,0,0,0,0,0,0,0,0,0,0,0,0,0,0,0,0,0
,3955999253.51067,0,2,0,8.1873685,0.268252849578857,2,39.995735168457,10,21.9999998807907,1.12835202514816E-007,-1.21478507253414E-007,-1.08250560515444E-005,-7.26510097592836E-006,0,0,0,0.0379374548792839,0.899169147014618,61440,0,0,0,0,0,0,0,0,0,0,0,0,0,0,0,0,0,0
,3955999350.32961,0,2,0,7.926521,0.268252849578857,2,39.995735168457,10,21.9999998807907,3.31530038977235E-008,-1.00774869338238E-007,-3.71023247680569E-006,-1.19565893328399E-005,0,0,0,0.0535587593913078,0.95454752445221,61440,0,0,0,0,0,0,0,0,0,0,0,0,0,0,0,0,0,0
,3955999445.91162,0,2,0,7.691848,0.268252849578857,2,39.995735168457,10,21.9999998807907,1.0530825989008E-008,-7.30777927060444E-008,5.06269998368225E-006,-1.0331071280234E-005,0,0,0,0.0484088771045208,0.890895009040833,61520,0,0,0,0,0,0,0,0,0,0,0,0,0,0,0,0,0,0
,3955999540.23553,0,2,0,7.477616,0.268252849578857,2,39.995735168457,10,21.9999998807907,2.18673875451714E-007,5.49106999869764E-008,1.07737432699651E-005,-4.11811515732552E-006,0,0,0,0.039379421621561,1.04446446895599,61440,0,0,0,0,0,0,0,0,0,0,0,0,0,0,0,0,0,0
,3955999634.65077,0,2,0,7.2804735,0.268252849578857,2,39.995735168457,10,21.9999998807907,5.96401577013239E-008,-1.05470533640073E-007,1.18170310088317E-005,3.61922025149397E-006,0,0,0,0.0485462062060833,0.860854029655457,59280,0,0,0,0,0,0,0,0,0,0,0,0,0,0,0,0,0,0
,3955999732.10454,0,2,0,7.081084,0.268252849578857,2,39.995735168457,10,21.9999998807907,8.83808723983748E-008,1.59073032524049E-009,6.72446003591176E-006,1.08834783532075E-005,0,0,0,0.0612149126827717,0.897143542766571,61520,0,0,0,0,0,0,0,0,0,0,0,0,0,0,0,0,0,0
,3955999827.45731,0,2,0,7.0671805,0.268252849578857,2,39.995735168457,10,21.9999998807907,2.56779514984373E-007,-1.53996126073253E-007,-1.36531298267073E-006,1.27219545902335E-005,0,0,0,0.0470699071884155,0.768430829048157,61520,0,0,0,0,0,0,0,0,0,0,0,0,0,0,0,0,0,0
,3955999925.36932,0,2,0,7.0862045,0.268252849578857,2,39.995735168457,10,21.9999998807907,3.40666787224109E-007,2.63920878751378E-006,-7.97250977484509E-005,7.76988308643922E-005,0,0,0,0.0478252246975899,0.383494436740875,59280,0,0,0,0,0,0,0,0,0,0,0,0,0,0,0,0,0,0
,3956000009.34946,0,2,0,5.025112,0.268252849578857,2,39.995735168457,10,21.9999998807907,1.89396260452668E-007,-1.54076715830342E-007,-1.14600425149547E-005,4.24755307903979E-006,0,0,0,0.0475505627691746,0.830950379371643,61520,0,0,0,0,0,0,0,0,0,0,0,0,0,0,0,0,0,0
,3956000107.9548,0,2,0,4.9959375,0.268252849578857,2,39.995735168457,10,21.9999998807907,-3.31617600046741E-009,-9.27228711589123E-008,-1.1399392860767E-005,-3.75329682356096E-006,0,0,0,0.0461429320275784,0.734304308891296,59280,0,0,0,0,0,0,0,0,0,0,0,0,0,0,0,0,0,0
,3956000208.21092,0,2,0,4.9962875,0.268252849578857,2,39.995735168457,10,21.9999998807907,1.58469674715889E-007,-1.52916335149911E-009,-5.31207797394018E-006,-1.0154678420804E-005,0,0,0,0.0472072400152683,0.618328988552094,61520,0,0,0,0,0,0,0,0,0,0,0,0,0,0,0,0,0,0
,3956000308.46593,0,2,0,4.997003,0.268252849578857,2,39.995735168457,10,21.9999998807907,1.40025719019832E-007,7.00824926980204E-008,3.22780647366017E-006,-1.0900149391091E-005,0,0,0,0.0459712669253349,0.617333352565765,61440,0,0,0,0,0,0,0,0,0,0,0,0,0,0,0,0,0,0
,3956000408.14521,0,2,0,4.9997365,0.268252849578857,2,39.995735168457,10,21.9999998807907,1.82297199557979E-008,-1.7421369591375E-007,8.79823892319109E-006,-6.78425021760631E-006,0,0,0,0.0467265844345093,0.746835708618164,61520,0,0,0,0,0,0,0,0,0,0,0,0,0,0,0,0,0,0
,3956000510.01674,0,2,0,4.9920845,0.268252849578857,2,39.995735168457,10,21.9999998807907,2.37402209002369E-010,9.70153593016221E-008,9.75069906417048E-006,2.30141290558095E-006,0,0,0,0.0694203898310661,0.727403461933136,59280,0,0,0,0,0,0,0,0,0,0,0,0,0,0,0,0,0,0
,3956000607.31573,0,2,0,5.0062925,0.268252849578857,2,39.995735168457,10,21.9999998807907,2.41218742758065E-007,8.65567102437126E-008,6.8569065660995E-006,1.062867067958E-005,0,0,0,0.0531811006367207,0.653245210647583,61520,0,0,0,0,0,0,0,0,0,0,0,0,0,0,0,0,0,0
,3956000697.98155,0,2,0,5.000534,0.268252849578857,2,39.995735168457,10,21.9999998807907,1.36754209734136E-007,2.71113993477456E-008,4.18499098486791E-007,1.09783522930229E-005,0,0,0,0.0442546419799328,0.644765079021454,61440,0,0,0,0,0,0,0,0,0,0,0,0,0,0,0,0,0,0
,3956000788.94514,0,2,0,5.0000535,0.268252849578857,2,39.995735168457,10,21.9999998807907,1.46165506365037E-008,-1.4332454156829E-007,-4.42247983301058E-006,9.28211102291243E-006,0,0,0,0.0415767021477222,0.759744703769684,59280,0,0,0,0,0,0,0,0,0,0,0,0,0,0,0,0,0,0
,3956000881.83785,0,2,0,4.999989,0.268252849578857,2,39.995735168457,10,21.9999998807907,8.9691681637305E-008,-9.34648838324392E-008,-1.00942706922069E-005,5.09649726154748E-006,0,0,0,0.0574383363127708,0.566109180450439,61520,0,0,0,0,0,0,0,0,0,0,0,0,0,0,0,0,0,0
,3956000974.88561,0,2,0,4.9997665,0.268252849578857,2,39.995735168457,10,21.9999998807907,2.5042416496035E-007,-1.44050133599194E-007,-1.23154795801383E-005,-1.89532954664173E-006,0,0,0,0.0346071980893612,0.895289599895477,59280,0,0,0,0,0,0,0,0,0,0,0,0,0,0,0,0,0,0
,3956001067.28305,0,2,0,4.998825,0.268252849578857,2,39.995735168457,10,21.9999998807907,1.30589128843894E-007,-9.89946116192186E-008,-7.13789086148609E-006,-7.60919829190243E-006,0,0,0,0.0495075173676014,0.655442476272583,59280,0,0,0,0,0,0,0,0,0,0,0,0,0,0,0,0,0,0
,3956001159.2862,0,2,0,5.0004695,0.268252849578857,2,39.995735168457,10,21.9999998807907,3.10906500544661E-007,-4.6901590167181E-008,-5.60313651476463E-007,-1.04120008472819E-005,0,0,0,0.0525631159543991,0.726339161396027,61440,0,0,0,0,0,0,0,0,0,0,0,0,0,0,0,0,0,0
,3956001254.00246,0,2,0,4.9999905,0.268252849578857,2,39.995735168457,10,21.9999998807907,6.95510227188834E-009,1.30854445501427E-007,5.21875199410715E-006,-6.63744503981434E-006,0,0,0,0.0355341769754887,0.765546917915344,59280,0,0,0,0,0,0,0,0,0,0,0,0,0,0,0,0,0,0
,3956001346.98383,0,2,0,5.000133,0.268252849578857,2,39.995735168457,10,21.9999998807907,-2.00772248604153E-007,-3.30543095117264E-008,8.3187487689429E-006,-1.92699098988669E-006,0,0,0,0.0366328172385693,0.733926653861999,59280,0,0,0,0,0,0,0,0,0,0,0,0,0,0,0,0,0,0
,3956001448.11116,0,2,0,8.607542,999.450500488281,2,39.995735168457,10,21.9999998807907,3.04048517136835E-005,-9.67100186244352E-006,2.26355932682054E-005,1.26932309285621E-005,0,0,0,0.0620045624673367,0.402068346738815,61520,0,0,0,0,0,0,0,0,0,0,0,0,0,0,0,0,0,0
,3956001561.80292,0,2,0,15.6628485,999.450500488281,2,39.995735168457,10,21.9999998807907,3.39973557856865E-005,-1.06877814687323E-005,7.7512322604889E-006,2.80540880339686E-005,0,0,0,0.0361864939332008,0.600819408893585,61440,0,0,0,0,0,0,0,0,0,0,0,0,0,0,0,0,0,0
,3956001674.90956,0,2,0,22.7444145,999.450500488281,2,39.995735168457,10,21.9999998807907,4.09585118177347E-005,-1.29690370158642E-005,-1.61861044034595E-005,2.97074766422156E-005,0,0,0,0.0543140731751919,0.716520071029663,61520,0,0,0,0,0,0,0,0,0,0,0,0,0,0,0,0,0,0
,3956001805.08258,0,2,0,30.8805525,999.450500488281,2,39.995735168457,10,21.9999998807907,4.68098223791458E-005,-1.52323045767844E-005,-3.68253204214852E-005,6.83872576701106E-006,0,0,0,0.0515331402420998,0.630208075046539,61440,0,0,0,0,0,0,0,0,0,0,0,0,0,0,0,0,0,0
,3956001934.073,0,2,0,38.8292865,999.450500488281,2,39.995735168457,10,21.9999998807907,4.05839964514598E-005,-1.31355418488965E-005,-2.46301406150451E-005,-2.14181218325393E-005,0,0,0,0.0464175902307034,0.710168540477753,61520,0,0,0,0,0,0,0,0,0,0,0,0,0,0,0,0,0,0
,3956002060.87674,0,2,0,44.74025,999.450500488281,2,39.995735168457,10,21.9999998807907,3.67394641216379E-005,-1.4059194654692E-005,1.19908520446188E-007,-2.88198571070097E-005,0,0,0,0.0463489256799221,0.665295898914337,59280,0,0,0,0,0,0,0,0,0,0,0,0,0,0,0,0,0,0
,3956002184.89812,0,2,0,48.366417,999.450500488281,2,39.995735168457,10,21.9999998807907,3.48579451383557E-005,-1.24032112580608E-005,2.14077645068755E-005,-1.53227083501406E-005,0,0,0,0.0507778227329254,0.642979741096497,59280,0,0,0,0,0,0,0,0,0,0,0,0,0,0,0,0,0,0
,3956002311.14257,0,2,0,51.509441,999.450500488281,2,39.995735168457,10,21.9999998807907,3.38107347488403E-005,-1.21463590403437E-005,2.59155549429124E-005,6.36072900306317E-006,0,0,0,0.067909762263298,0.596184492111206,61440,0,0,0,0,0,0,0,0,0,0,0,0,0,0,0,0,0,0
,3956002503.49627,0,2,0,59.211985,999.450500488281,2,39.995735168457,10,21.9999998807907,3.12798729282804E-005,-1.30460339278216E-005,-6.52941196221946E-007,2.65491180471145E-005,0,0,0,0.0434306599199772,0.692040979862213,61520,0,0,0,0,0,0,0,0,0,0,0,0,0,0,0,0,0,0
,3956002661.98669,0,2,0,66.6039695,999.450500488281,2,39.995735168457,10,21.9999998807907,2.85285514110001E-005,-1.02877893368714E-005,-2.53220023296308E-005,1.20595241241972E-005,0,0,0,0.0583309791982174,0.661450684070587,59280,0,0,0,0,0,0,0,0,0,0,0,0,0,0,0,0,0,0
,3956002780.97179,0,2,0,72.48267,999.450500488281,2,39.995735168457,10,21.9999998807907,2.65971102635376E-005,-9.35493062570458E-006,-2.50079028774053E-005,-9.93127014226047E-006,0,0,0,0.0453532822430134,0.644387364387512,61440,0,0,0,0,0,0,0,0,0,0,0,0,0,0,0,0,0,0
,3956002904.74875,0,2,0,78.8274115,999.450500488281,2,39.995735168457,10,21.9999998807907,2.47492662310833E-005,-8.79683193488745E-006,-7.87466524343472E-006,-2.43825652432861E-005,0,0,0,0.0434993244707584,0.737497210502625,59280,0,0,0,0,0,0,0,0,0,0,0,0,0,0,0,0,0,0
,3956003025.1369,0,2,0,85.285778,999.450500488281,2,39.995735168457,10,21.9999998807907,2.29416964430129E-005,-8.24963990453398E-006,1.21329330795561E-005,-2.02828268811572E-005,0,0,0,0.0542797408998013,0.503108978271484,59280,0,0,0,0,0,0,0,0,0,0,0,0,0,0,0,0,0,0
,3956003147.09384,0,2,0,92.1051485,999.450500488281,2,39.995735168457,10,21.9999998807907,2.17024717130698E-005,-7.42166866984917E-006,2.50181910814717E-005,-2.47097409555863E-006,0,0,0,0.0482715480029583,0.706185936927795,59280,0,0,0,0,0,0,0,0,0,0,0,0,0,0,0,0,0,0
,3956003271.01216,0,2,0,99.260452,999.450500488281,2,39.995735168457,10,21.9999998807907,2.02512001123978E-005,-7.19062882126309E-006,1.89194161066553E-005,1.80792867467972E-005,0,0,0,0.0431903302669525,0.741308152675629,59280,0,0,0,0,0,0,0,0,0,0,0,0,0,0,0,0,0,0
,3956003398.25443,0,2,0,106.883152,999.450500488281,2,39.995735168457,10,21.9999998807907,1.88328667718451E-005,-6.50660422252258E-006,-1.32136653974158E-006,2.56005605479004E-005,0,0,0,0.0506748259067535,0.649777591228485,61440,0,0,0,0,0,0,0,0,0,0,0,0,0,0,0,0,0,0
,3956003523.44131,0,2,0,114.4994885,999.450500488281,2,39.995735168457,10,21.9999998807907,1.79547532752622E-005,-6.38284336673678E-006,-2.1787123841932E-005,1.67559119290672E-005,0,0,0,0.0485118739306927,0.574246048927307,61520,0,0,0,0,0,0,0,0,0,0,0,0,0,0,0,0,0,0
,3956003648.08135,0,2,0,122.260822,999.450500488281,2,39.995735168457,10,21.9999998807907,1.71130395756336E-005,-5.82301572649158E-006,-2.58800046140095E-005,-5.72301541978959E-006,0,0,0,0.0495075173676014,0.614655435085297,61520,0,0,0,0,0,0,0,0,0,0,0,0,0,0,0,0,0,0
,3956003772.72527,0,2,0,130.080391,999.450500488281,2,39.995735168457,10,21.9999998807907,1.59794399223756E-005,-5.47456465938012E-006,-1.14084941742476E-005,-2.26432184717851E-005,0,0,0,0.0752225890755653,0.630139410495758,61520,0,0,0,0,0,0,0,0,0,0,0,0,0,0,0,0,0,0
,3956003897.76541,0,2,0,138.108406,999.450500488281,2,39.995735168457,10,21.9999998807907,1.52141064972966E-005,-4.95761560159735E-006,8.96014989848482E-006,-1.89898273674771E-005,0,0,0,0.0522884540259838,0.665089905261993,61520,0,0,0,0,0,0,0,0,0,0,0,0,0,0,0,0,0,0
,3956004021.79947,0,2,0,146.060959,999.450500488281,2,39.995735168457,10,21.9999998807907,1.42497283377452E-005,-4.68700272904243E-006,1.75315763044637E-005,-4.35210813520825E-006,0,0,0,0.0501255057752132,0.699525475502014,59280,0,0,0,0,0,0,0,0,0,0,0,0,0,0,0,0,0,0
,3956004147.20672,0,2,0,154.2774965,999.450500488281,2,39.995735168457,10,21.9999998807907,1.3507094081433E-005,-4.36482332588639E-006,1.54282133735251E-005,1.3238774954516E-005,0,0,0,0.0415767021477222,0.565353870391846,59280,0,0,0,0,0,0,0,0,0,0,0,0,0,0,0,0,0,0
,3956004271.93475,0,2,0,162.4044645,999.450500488281,2,39.995735168457,10,21.9999998807907,1.2935543054482E-005,-4.26225278715719E-006,2.31013345342035E-007,2.15604341065045E-005,0,0,0,0.0419200286269188,0.576855301856995,61440,0,0,0,0,0,0,0,0,0,0,0,0,0,0,0,0,0,0
,3956004396.85702,0,2,0,170.68293,999.450500488281,2,39.995735168457,10,21.9999998807907,1.26069380712579E-005,-4.18332319895853E-006,-1.76267203642055E-005,1.59699739015196E-005,0,0,0,0.0522884540259838,0.806711614131928,61440,0,0,0,0,0,0,0,0,0,0,0,0,0,0,0,0,0,0
,3956004523.06773,0,2,0,179.050896,999.450500488281,2,39.995735168457,10,21.9999998807907,1.18556645247736E-005,-4.20547348767286E-006,-2.25207368202973E-005,-2.00769318325911E-006,0,0,0,0.0443919710814953,0.721429586410522,59280,0,0,0,0,0,0,0,0,0,0,0,0,0,0,0,0,0,0
,3956004646.12835,0,2,0,187.2206425,999.450500488281,2,39.995735168457,10,21.9999998807907,1.11884601210477E-005,-3.72601789422333E-006,-1.10021683212835E-005,-1.61950374604203E-005,0,0,0,0.042778342962265,0.777940988540649,59280,0,0,0,0,0,0,0,0,0,0,0,0,0,0,0,0,0,0
,3956004773.90109,0,2,0,195.73719,999.450500488281,2,39.995735168457,10,21.9999998807907,1.07239329736331E-005,-3.48758294421714E-006,6.82360314385733E-006,-1.84187047125306E-005,0,0,0,0.0510524846613407,0.609471201896668,61520,0,0,0,0,0,0,0,0,0,0,0,0,0,0,0,0,0,0
,3956004896.70448,0,2,0,204.0040055,999.450500488281,2,39.995735168457,10,21.9999998807907,1.0357451174059E-005,-3.46516776517092E-006,1.69022587215295E-005,-6.4076057242346E-006,0,0,0,0.0452846176922321,0.566830217838287,59280,0,0,0,0,0,0,0,0,0,0,0,0,0,0,0,0,0,0
,3956005018.37743,0,2,0,212.2233275,999.450500488281,2,39.995735168457,10,21.9999998807907,9.97580264083808E-006,-3.19467858389544E-006,1.75262666743947E-005,1.13194237201242E-005,0,0,0,0.0546230673789978,0.79884946346283,59280,0,0,0,0,0,0,0,0,0,0,0,0,0,0,0,0,0,0
,3956005143.39069,0,2,0,220.672302,999.450500488281,2,39.995735168457,10,21.9999998807907,9.60099168878514E-006,-3.1565971312375E-006,3.19751529787027E-006,2.11270689760568E-005,0,0,0,0.0355685092508793,0.65001791715622,61520,0,0,0,0,0,0,0,0,0,0,0,0,0,0,0,0,0,0
,3956005266.30433,0,2,0,228.9874115,999.450500488281,2,39.995735168457,10,21.9999998807907,9.45111787586939E-006,-3.15238389703154E-006,-1.50825489981798E-005,1.82540406967746E-005,0,0,0,0.059635616838932,0.72819310426712,61520,0,0,0,0,0,0,0,0,0,0,0,0,0,0,0,0,0,0
,3956005387.00859,0,2,0,237.184265,999.450500488281,2,39.995735168457,10,21.9999998807907,8.95909488463076E-006,-3.01490831589035E-006,-2.13381154026138E-005,1.21154312182625E-006,0,0,0,0.0523227863013744,0.772035777568817,61440,0,0,0,0,0,0,0,0,0,0,0,0,0,0,0,0,0,0
,3956005509.70423,0,2,0,245.458504,999.450500488281,2,39.995735168457,10,21.9999998807907,8.96760957402876E-006,-2.99288740279735E-006,-1.37238930619787E-005,-1.30804628497572E-005,0,0,0,0.0702443718910217,0.639821171760559,59280,0,0,0,0,0,0,0,0,0,0,0,0,0,0,0,0,0,0
,3956005632.45625,0,2,0,253.83268,999.450500488281,2,39.995735168457,10,21.9999998807907,8.57867871673079E-006,-2.93887387670111E-006,1.43230806770589E-006,-1.84394557436462E-005,0,0,0,0.0683560818433762,0.748449325561523,59280,0,0,0,0,0,0,0,0,0,0,0,0,0,0,0,0,0,0
,3956005754.06919,0,2,0,262.1170045,999.450500488281,2,39.995735168457,10,21.9999998807907,8.0119298218051E-006,-2.82478208646353E-006,1.21746297736536E-005,-8.8114247773774E-006,0,0,0,0.0460055992007256,0.677209317684174,61440,0,0,0,0,0,0,0,0,0,0,0,0,0,0,0,0,0,0
,3956005874.53059,0,2,0,270.312424,999.450500488281,2,39.995735168457,10,21.9999998807907,8.0392237578053E-006,-2.82320570477168E-006,1.63833356054965E-005,5.27997417520965E-006,0,0,0,0.0392077565193176,0.849798977375031,59280,0,0,0,0,0,0,0,0,0,0,0,0,0,0,0,0,0,0
,3956005993.32296,0,2,0,278.1076965,999.450500488281,2,39.995735168457,10,21.9999998807907,7.62984018365387E-006,-2.77801473202999E-006,6.7088599280396E-006,1.44005925903912E-005,0,0,0,0.0664677917957306,0.826521515846252,61440,0,0,0,0,0,0,0,0,0,0,0,0,0,0,0,0,0,0
,3956006108.10515,0,2,0,284.7227785,999.450500488281,2,39.995735168457,10,21.9999998807907,7.66365701565519E-006,-2.61558602687728E-006,-5.70850716030691E-006,1.47677819768433E-005,0,0,0,0.0448726266622543,0.638962864875793,61440,0,0,0,0,0,0,0,0,0,0,0,0,0,0,0,0,0,0
,3956006223.91368,0,2,0,290.3454745,999.450500488281,2,39.995735168457,10,21.9999998807907,7.20136267773341E-006,-2.74316971626831E-006,-1.20944541777135E-005,7.26745656720595E-006,0,0,0,0.0738149583339691,0.736913561820984,61520,0,0,0,0,0,0,0,0,0,0,0,0,0,0,0,0,0,0
,3956006341.32899,0,2,0,294.96727,999.450500488281,2,39.995735168457,10,21.9999998807907,7.14355655873078E-006,-2.67730047198711E-006,-1.22556184578571E-005,-3.81077097699745E-006,0,0,0,0.0321009233593941,0.955268502235413,61520,0,0,0,0,0,0,0,0,0,0,0,0,0,0,0,0,0,0
,3956006468.97611,0,2,0,298.564819,999.450500488281,2,39.995735168457,10,21.9999998807907,7.19608351573697E-006,-2.66029519480071E-006,-4.65377888758667E-006,-1.14856402433361E-005,0,0,0,0.0471729077398777,1.15209698677063,61440,0,0,0,0,0,0,0,0,0,0,0,0,0,0,0,0,0,0
,3956006594.31287,0,2,0,299.960037,999.450500488281,2,39.995735168457,10,21.9999998807907,7.55954351916444E-006,-3.17459694088029E-006,5.06016431245371E-006,-1.00110710263834E-005,0,0,0,0.06536915153265,0.405261278152466,61520,0,0,0,0,0,0,0,0,0,0,0,0,0,0,0,0,0,0
,3956006716.82338,0,2,0,300.3414765,999.450500488281,2,39.995735168457,10,21.9999998807907,7.0999099079927E-006,-2.44381953962147E-006,9.60952183959307E-006,2.69588333878801E-008,0,0,0,0.0356715060770512,0.562984943389893,59280,0,0,0,0,0,0,0,0,0,0,0,0,0,0,0,0,0,0
,3956006837.75746,0,2,0,300.382858,999.450500488281,2,39.995735168457,10,21.9999998807907,7.04417016095249E-006,-2.32171737479803E-006,6.72548048896715E-006,8.72378222993575E-006,0,0,0,0.0437739863991737,0.576374650001526,61520,0,0,0,0,0,0,0,0,0,0,0,0,0,0,0,0,0,0
,3956006971.17481,0,2,0,300.2094575,999.450500488281,2,39.995735168457,10,21.9999998807907,7.17759348844993E-006,-2.30578530135972E-006,-2.6715756575868E-006,9.67019605013775E-006,0,0,0,0.0427440106868744,1.03042244911194,61520,0,0,0,0,0,0,0,0,0,0,0,0,0,0,0,0,0,0
,3956007098.89405,0,2,0,299.193878,999.450500488281,2,39.995735168457,10,21.9999998807907,7.21916558177327E-006,-2.33384776038292E-006,-7.59399335947819E-006,4.64523691334762E-006,0,0,0,0.0599789433181286,1.18931341171265,61520,0,0,0,0,0,0,0,0,0,0,0,0,0,0,0,0,0,0
,3956007228.04259,0,2,0,295.901474,999.450500488281,2,39.995735168457,10,21.9999998807907,7.18430737833842E-006,-2.58413433584792E-006,-8.48150557430927E-006,-2.04603657039115E-006,0,0,0,0.0421603545546532,0.897864520549774,61440,0,0,0,0,0,0,0,0,0,0,0,0,0,0,0,0,0,0
,3956007359.6511,0,2,0,290.694168,999.450500488281,2,39.995735168457,10,21.9999998807907,7.28053692000685E-006,-2.64894470092258E-006,-3.2913708309934E-006,-7.20186471880879E-006,0,0,0,0.0520137958228588,0.794523596763611,61440,0,0,0,0,0,0,0,0,0,0,0,0,0,0,0,0,0,0
,3956007490.5312,0,2,0,284.5513615,999.450500488281,2,39.995735168457,10,21.9999998807907,7.38787775844685E-006,-2.68840085482225E-006,3.88771377402009E-006,-5.86138276048587E-006,0,0,0,0.0486492067575455,0.731008410453796,61520,0,0,0,0,0,0,0,0,0,0,0,0,0,0,0,0,0,0
,3956007616.95576,0,2,0,278.033234,999.450500488281,2,39.995735168457,10,21.9999998807907,7.66705124988221E-006,-2.53386656368093E-006,8.88381418917561E-006,1.32739899072476E-006,0,0,0,0.0500225052237511,0.878672599792481,61520,0,0,0,0,0,0,0,0,0,0,0,0,0,0,0,0,0,0
,3956007740.55836,0,2,0,271.399963,999.450500488281,2,39.995735168457,10,21.9999998807907,7.71255326981191E-006,-2.76882542493695E-006,7.15447549737291E-006,9.0864414232783E-006,0,0,0,0.0589489676058292,0.943423807621002,59280,0,0,0,0,0,0,0,0,0,0,0,0,0,0,0,0,0,0
,3956007870.73034,0,2,0,264.101654,999.450500488281,2,39.995735168457,10,21.9999998807907,8.03067359811394E-006,-2.67766608885722E-006,-3.29874046656187E-006,1.22628734970931E-005,0,0,0,0.0421603545546532,0.817148745059967,61440,0,0,0,0,0,0,0,0,0,0,0,0,0,0,0,0,0,0
,3956008001.80902,0,2,0,256.4669345,999.450500488281,2,39.995735168457,100,21.9999998807907,8.25781080493471E-006,-2.68311919171538E-006,-1.30235212054686E-005,6.83695543557405E-006,0,0,0,0.060219269245863,0.856596827507019,59280,0,0,0,0,0,0,0,0,0,0,0,0,0,0,0,0,0,0
,3956008130.02211,0,2,0,248.8221055,999.450500488281,2,39.995735168457,10,21.9999998807907,8.44482565298676E-006,-2.84882162304712E-006,-1.50097976074903E-005,-6.42113263893407E-006,0,0,0,0.0392420887947082,0.868269860744476,61520,0,0,0,0,0,0,0,0,0,0,0,0,0,0,0,0,0,0
,3956008250.93524,0,2,0,241.536667,999.450500488281,2,39.995735168457,10,21.9999998807907,8.85143526829779E-006,-2.9533987344621E-006,-4.85417558593326E-006,-1.61721491167555E-005,0,0,0,0.0489581972360611,0.843069791793823,61520,0,0,0,0,0,0,0,0,0,0,0,0,0,0,0,0,0,0
,3956008376.7774,0,2,0,233.882645,999.450500488281,2,39.995735168457,10,21.9999998807907,9.18899877433432E-006,-3.06932247440272E-006,1.12412417365704E-005,-1.52965494635282E-005,0,0,0,0.0513271428644657,0.86160933971405,61440,0,0,0,0,0,0,0,0,0,0,0,0,0,0,0,0,0,0
,3956008505.82713,0,2,0,225.909897,999.450500488281,2,39.995735168457,10,21.9999998807907,9.38271386985434E-006,-3.19145669891441E-006,2.0158562620054E-005,3.98877148199972E-007,0,0,0,0.057609997689724,0.891924977302551,61440,0,0,0,0,0,0,0,0,0,0,0,0,0,0,0,0,0,0
,3956008633.502,0,2,0,217.9441985,999.450500488281,2,39.995735168457,10,21.9999998807907,9.70320252235979E-006,-3.39467442245223E-006,1.29149866552325E-005,1.66202025866369E-005,0,0,0,0.0523571185767651,0.805956304073334,61520,0,0,0,0,0,0,0,0,0,0,0,0,0,0,0,0,0,0
,3956008763.20426,0,2,0,209.7926635,999.450500488281,2,39.995735168457,10,21.9999998807907,9.88634292298229E-006,-3.30892294186924E-006,-4.79862228530692E-006,1.95737247850047E-005,0,0,0,0.0483058802783489,0.804892003536224,61440,0,0,0,0,0,0,0,0,0,0,0,0,0,0,0,0,0,0
,3956008885.24756,0,2,0,202.0868075,999.450500488281,2,39.995735168457,10,21.9999998807907,1.03102247521747E-005,-3.46879232893116E-006,-1.77100864675594E-005,1.05000408439082E-005,0,0,0,0.0530094392597675,0.755796492099762,61520,0,0,0,0,0,0,0,0,0,0,0,0,0,0,0,0,0,0
,3956009014.60421,0,2,0,193.937561,999.450500488281,2,39.995735168457,10,21.9999998807907,1.07367259261082E-005,-3.47131913258636E-006,-1.83762858796399E-005,-6.90925207891269E-006,0,0,0,0.0449412912130356,1.06544160842896,61440,0,0,0,0,0,0,0,0,0,0,0,0,0,0,0,0,0,0
,3956009143.91775,0,2,0,185.737854,999.450500488281,2,39.995735168457,10,21.9999998807907,1.13453506855876E-005,-3.55195334122982E-006,-4.4890721255797E-006,-1.81738032551948E-005,0,0,0,0.0504001639783382,0.812754154205322,59280,0,0,0,0,0,0,0,0,0,0,0,0,0,0,0,0,0,0
,3956009274.78782,0,2,0,177.4108355,999.450500488281,2,39.995735168457,10,21.9999998807907,1.17807458082098E-005,-3.90096784030902E-006,1.22336386993993E-005,-1.53181481437059E-005,0,0,0,0.052940770983696,0.889796376228333,59280,0,0,0,0,0,0,0,0,0,0,0,0,0,0,0,0,0,0
,3956009399.72097,0,2,0,169.4769975,999.450500488281,2,39.995735168457,10,21.9999998807907,1.22424353321549E-005,-3.92651145375567E-006,1.85175686056027E-005,8.62024251091498E-007,0,0,0,0.0619358979165554,0.787348091602325,61440,0,0,0,0,0,0,0,0,0,0,0,0,0,0,0,0,0,0
,3956009523.86609,0,2,0,161.5897215,999.450500488281,2,39.995735168457,10,21.9999998807907,1.25954911709414E-005,-4.04028378397925E-006,1.12990319394157E-005,1.51640488184057E-005,0,0,0,0.0500225052237511,0.857420802116394,61520,0,0,0,0,0,0,0,0,0,0,0,0,0,0,0,0,0,0
,3956009653.27556,0,2,0,153.4847185,999.450500488281,2,39.995735168457,10,21.9999998807907,1.33801986521576E-005,-4.23272194893798E-006,-5.69516942050541E-006,1.90769424079917E-005,0,0,0,0.0528034418821335,0.802420079708099,61520,0,0,0,0,0,0,0,0,0,0,0,0,0,0,0,0,0,0
,3956009837.60519,0,2,0,141.779335,999.450500488281,2,39.995735168457,100,21.9999998807907,1.44929990710807E-005,-4.51509095000802E-006,-1.9710745618795E-005,1.53536018387967E-006,0,0,0,0.0382807776331902,1.06173372268677,59280,0,0,0,0,0,0,0,0,0,0,0,0,0,0,0,0,0,0
,3956009971.86546,0,2,0,133.208519,999.450500488281,2,39.995735168457,10,21.9999998807907,1.51120939335669E-005,-4.82167342852335E-006,-1.22117817227263E-005,-1.3259387742437E-005,0,0,0,0.0298349745571613,0.876406669616699,61520,0,0,0,0,0,0,0,0,0,0,0,0,0,0,0,0,0,0
,3956010080.384,0,2,0,126.4687885,999.450500488281,2,39.995735168457,10,21.9999998807907,1.6264470104943E-005,-4.8871561375563E-006,1.36524192839715E-006,-1.82928779395297E-005,0,0,0,0.0436366535723209,0.890242695808411,59280,0,0,0,0,0,0,0,0,0,0,0,0,0,0,0,0,0,0
,3956010190.36728,0,2,0,119.502777,999.450500488281,2,39.995735168457,10,21.9999998807907,1.67029211297631E-005,-5.32426702193334E-006,1.3612939255836E-005,-1.11242470666184E-005,0,0,0,0.0717206671833992,0.812582492828369,61440,0,0,0,0,0,0,0,0,0,0,0,0,0,0,0,0,0,0
,3956010288.01981,0,2,0,113.353973,999.450500488281,2,39.995735168457,10,21.9999998807907,1.72021682374179E-005,-5.59476939088199E-006,1.73856842593523E-005,1.09937457182241E-006,0,0,0,0.044906958937645,0.910636246204376,61520,0,0,0,0,0,0,0,0,0,0,0,0,0,0,0,0,0,0
,3956010389.59367,0,2,0,106.057034,999.450500488281,2,39.995735168457,10,21.9999998807907,1.80774750333512E-005,-5.97030975768575E-006,1.34897290990921E-005,1.352454728476E-005,0,0,0,0.0334055572748184,0.819620668888092,61440,0,0,0,0,0,0,0,0,0,0,0,0,0,0,0,0,0,0
,3956010505.13157,0,2,0,91.308758,999.450500488281,2,39.995735168457,10,21.9999998807907,2.04945263249101E-005,-6.75624551149667E-006,5.82924940317753E-007,2.14786541619105E-005,0,0,0,0.0418170318007469,0.94771534204483,59280,0,0,0,0,0,0,0,0,0,0,0,0,0,0,0,0,0,0
,3956010617.61691,0,2,0,73.5678215,999.450500488281,2,39.995735168457,10,21.9999998807907,2.44539442064706E-005,-8.10416167951189E-006,-1.52291213453282E-005,1.75853292603279E-005,0,0,0,0.0491641946136951,0.944076120853424,61520,0,0,0,0,0,0,0,0,0,0,0,0,0,0,0,0,0,0
,3956010718.26675,0,2,0,58.0592845,999.450500488281,2,39.995735168457,10,21.9999998807907,2.99001749226591E-005,-9.81585162662668E-006,-2.5713201466715E-005,3.5401565128268E-006,0,0,0,0.0434993244707584,1.01184856891632,59280,0,0,0,0,0,0,0,0,0,0,0,0,0,0,0,0,0,0
,3956010811.07254,0,2,0,45.011488,999.450500488281,2,39.995735168457,10,21.9999998807907,3.64940678991843E-005,-1.18006555567263E-005,-2.5644376364653E-005,-1.44147788887494E-005,0,0,0,0.0359461680054665,0.938136577606201,59280,0,0,0,0,0,0,0,0,0,0,0,0,0,0,0,0,0,0
,3956010921.94383,0,2,0,31.196372,999.450500488281,2,39.995735168457,10,21.9999998807907,4.73818072350696E-005,-1.55676771100843E-005,-1.1697598893079E-005,-3.59854457201436E-005,0,0,0,0.052666112780571,0.430701673030853,61520,0,0,0,0,0,0,0,0,0,0,0,0,0,0,0,0,0,0
,3956011020.38081,0,2,0,24.516456,999.450500488281,2,39.995735168457,10,21.9999998807907,4.54934197477996E-005,-1.4579069102183E-005,1.55652342073154E-005,-3.22210689773783E-005,0,0,0,0.0419200286269188,0.866415917873383,59280,0,0,0,0,0,0,0,0,0,0,0,0,0,0,0,0,0,0
,3956011121.91399,0,2,0,17.1938345,999.450500488281,2,39.995735168457,10,21.9999998807907,3.62324717571028E-005,-1.15785360321752E-005,2.67480245383922E-005,-1.13054284156533E-005,0,0,0,0.0628628730773926,0.425071150064468,61520,0,0,0,0,0,0,0,0,0,0,0,0,0,0,0,0,0,0
,3956011213.22144,0,2,0,10.985583,999.450500488281,2,39.995735168457,10,21.9999998807907,3.24017273669597E-005,-1.03530774140381E-005,2.51586261583725E-005,7.21040942153195E-006,0,0,0,0.0665707886219025,0.848940670490265,61520,0,0,0,0,0,0,0,0,0,0,0,0,0,0,0,0,0,0
,3956011312.87814,0,2,0,9.3989725,999.450500488281,2,39.995735168457,10,21.9999998807907,3.14589924528263E-005,-1.01078867373872E-005,1.46100855999975E-005,2.18532113649417E-005,0,0,0,0.0300066377967596,0.869093835353851,61520,0,0,0,0,0,0,0,0,0,0,0,0,0,0,0,0,0,0
,3956011407.18234,0,2,0,9.025857,999.450500488281,2,39.995735168457,10,21.9999998807907,3.13462915073615E-005,-1.00615052360808E-005,-2.01973648472631E-006,2.70748787443154E-005,0,0,0,0.0499538406729698,0.852682888507843,59280,0,0,0,0,0,0,0,0,0,0,0,0,0,0,0,0,0,0
,3956011504.85036,0,2,0,8.6065585,999.450500488281,2,39.995735168457,10,21.9999998807907,3.10444229398854E-005,-1.01614932646044E-005,-1.71773663169006E-005,2.09322697628522E-005,0,0,0,0.044323306530714,0.87894731760025,59280,0,0,0,0,0,0,0,0,0,0,0,0,0,0,0,0,0,0
,3956011601.98003,0,2,0,8.225547,999.450500488281,2,39.995735168457,10,21.9999998807907,3.09290589939337E-005,-9.89078489510575E-006,-2.59850748989265E-005,4.63790183857782E-006,0,0,0,0.0413707084953785,0.865420281887054,59280,0,0,0,0,0,0,0,0,0,0,0,0,0,0,0,0,0,0
,3956011700.18252,0,2,0,7.873368,999.450500488281,2,39.995735168457,10,21.9999998807907,3.08638336719014E-005,-1.00453416962409E-005,-2.3997388780117E-005,-1.24699681691709E-005,0,0,0,0.0393107570707798,0.896834552288055,59280,0,0,0,0,0,0,0,0,0,0,0,0,0,0,0,0,0,0
,3956011796.04864,0,2,0,7.5520965,999.450500488281,2,39.995735168457,10,21.9999998807907,3.05507346638478E-005,-1.00543111329898E-005,-1.0766201739898E-005,-2.49030981649412E-005,0,0,0,0.0311052780598402,0.841421842575073,61440,0,0,0,0,0,0,0,0,0,0,0,0,0,0,0,0,0,0
,3956011892.00269,0,2,0,7.2674305,999.450500488281,2,39.995735168457,10,21.9999998807907,3.04387922369642E-005,-9.87542989605572E-006,7.96661515778396E-006,-2.59802236541873E-005,0,0,0,0.0333712249994278,0.814779758453369,59280,0,0,0,0,0,0,0,0,0,0,0,0,0,0,0,0,0,0
,3956011989.01555,0,2,0,6.997104,999.450500488281,2,39.995735168457,10,21.9999998807907,3.02703811030369E-005,-9.80875211098464E-006,2.11534788832068E-005,-1.35200480144704E-005,0,0,0,0.0451816208660603,0.848734676837921,59280,0,0,0,0,0,0,0,0,0,0,0,0,0,0,0,0,0,0
,3956012086.3223,0,2,0,7.028567,999.450500488281,2,39.995735168457,10,21.9999998807907,3.02179578284267E-005,-9.74203521764139E-006,2.3950713512022E-005,4.21433060182608E-006,0,0,0,0.0889899358153343,0.46712851524353,61440,0,0,0,0,0,0,0,0,0,0,0,0,0,0,0,0,0,0
,3956012174.98854,0,2,0,5.137346,999.450500488281,2,39.995735168457,10,21.9999998807907,2.99717885354767E-005,-9.90267653833143E-006,1.8557542716735E-005,1.73255939444061E-005,0,0,0,0.0578503236174583,0.863394677639008,61520,0,0,0,0,0,0,0,0,0,0,0,0,0,0,0,0,0,0
,3956012274.08304,0,2,0,4.9971595,999.450500488281,2,39.995735168457,10,21.9999998807907,3.00390383927152E-005,-9.68493986874819E-006,3.09550046040385E-006,2.62734793068375E-005,0,0,0,0.0372164696455002,0.586571395397186,59280,0,0,0,0,0,0,0,0,0,0,0,0,0,0,0,0,0,0
,3956012377.95421,0,2,0,8.156483,999.450500488281,2,39.995735168457,10,21.9999998807907,3.04921504721278E-005,-9.77351828623796E-006,-1.49975148815429E-005,2.23158676817548E-005,0,0,0,0.0632062032818794,0.447867959737778,59280,0,0,0,0,0,0,0,0,0,0,0,0,0,0,0,0,0,0
,3956012492.39046,0,2,0,15.298134,999.450500488281,2,39.995735168457,10,21.9999998807907,3.39534853992518E-005,-1.06472371044219E-005,-2.91489996016026E-005,4.69120368506992E-006,0,0,0,0.059944611042738,0.657262086868286,59280,0,0,0,0,0,0,0,0,0,0,0,0,0,0,0,0,0,0
,3956012611.01105,0,2,0,22.7639875,999.450500488281,2,39.995735168457,10,21.9999998807907,4.08366940973792E-005,-1.32414879772114E-005,-2.65438302449184E-005,-2.0257182768546E-005,0,0,0,0.0617985688149929,0.662549316883087,61440,0,0,0,0,0,0,0,0,0,0,0,0,0,0,0,0,0,0
,3956012739.82062,0,2,0,30.8202605,999.450500488281,2,39.995735168457,10,21.9999998807907,4.68793987238314E-005,-1.53123601194238E-005,-2.82034449128332E-007,-3.57049066224135E-005,0,0,0,0.0602879337966442,0.616715371608734,59280,0,0,0,0,0,0,0,0,0,0,0,0,0,0,0,0,0,0
,3956012867.01009,0,2,0,38.6842385,999.450500488281,2,39.995735168457,10,21.9999998807907,4.03857411583886E-005,-1.35006021082518E-005,2.27401778829517E-005,-1.82491257874062E-005,0,0,0,0.0456966087222099,0.630929052829742,61520,0,0,0,0,0,0,0,0,0,0,0,0,0,0,0,0,0,0
,3956012991.68667,0,2,0,44.500116,999.450500488281,2,39.995735168457,10,21.9999998807907,3.66237691196147E-005,-1.21365992526989E-005,2.27364616876002E-005,5.77413129576598E-006,0,0,0,0.0817801058292389,0.557011067867279,61520,0,0,0,0,0,0,0,0,0,0,0,0,0,0,0,0,0,0
,3956013114.88054,0,2,0,48.08827,999.450500488281,2,39.995735168457,10,21.9999998807907,3.47678796970286E-005,-1.14076565296273E-005,1.02656949820812E-005,2.14211249840446E-005,0,0,0,0.0712056830525398,0.521408259868622,61520,0,0,0,0,0,0,0,0,0,0,0,0,0,0,0,0,0,0
,3956013235.4003,0,2,0,50.7022015,999.450500488281,2,39.995735168457,10,21.9999998807907,3.3945147151826E-005,-1.09725906440872E-005,-9.04626722331159E-006,2.26522224693326E-005,0,0,0,0.0548290610313416,0.655545473098755,61520,0,0,0,0,0,0,0,0,0,0,0,0,0,0,0,0,0,0
,3956013417.86791,0,2,0,57.5203665,999.450500488281,2,39.995735168457,10,21.9999998807907,3.14020689984318E-005,-1.01050090961508E-005,-2.20024812733755E-005,-1.54664553519979E-006,0,0,0,0.0536960884928703,0.609436869621277,61440,0,0,0,0,0,0,0,0,0,0,0,0,0,0,0,0,0,0
,3956013583.00499,0,2,0,65.081997,999.450500488281,2,39.995735168457,10,21.9999998807907,2.85155110759661E-005,-8.91617037268588E-006,-6.20937089479412E-006,-1.72337149706436E-005,0,0,0,0.0581249855458736,0.58348149061203,59280,0,0,0,0,0,0,0,0,0,0,0,0,0,0,0,0,0,0
,3956013703.44375,0,2,0,70.8891295,999.450500488281,2,39.995735168457,10,21.9999998807907,2.65201033471385E-005,-8.36714298202423E-006,8.56993847264675E-006,-1.36645776365185E-005,0,0,0,0.0447009652853012,0.792944252490997,61520,0,0,0,0,0,0,0,0,0,0,0,0,0,0,0,0,0,0
,3956013826.47651,0,2,0,77.0598485,999.450500488281,2,39.995735168457,10,21.9999998807907,2.46297950070584E-005,-7.86466716817813E-006,1.51373806147603E-005,-2.14586452784715E-006,0,0,0,0.0809561237692833,0.589352309703827,61440,0,0,0,0,0,0,0,0,0,0,0,0,0,0,0,0,0,0
,3956013945.9874,0,2,0,83.365551,999.450500488281,2,39.995735168457,10,21.9999998807907,2.30327368626604E-005,-7.17648754289257E-006,1.12013522084453E-005,1.08438025563373E-005,0,0,0,0.0608029253780842,0.69351726770401,61440,0,0,0,0,0,0,0,0,0,0,0,0,0,0,0,0,0,0
,3956014067.28855,0,2,0,89.9497645,999.450500488281,2,39.995735168457,10,21.9999998807907,2.14742904063314E-005,-6.78598053127644E-006,-2.71529700057727E-007,1.48848866956541E-005,0,0,0,0.0687680691480637,0.760225355625153,59280,0,0,0,0,0,0,0,0,0,0,0,0,0,0,0,0,0,0
,3956014188.18078,0,2,0,96.790104,999.450500488281,2,39.995735168457,10,21.9999998807907,2.01982493308606E-005,-6.24869880994083E-006,-1.05942826849059E-005,1.01465439001913E-005,0,0,0,0.059360958635807,0.674943327903748,61440,0,0,0,0,0,0,0,0,0,0,0,0,0,0,0,0,0,0
,3956014311.85238,0,2,0,104.037754,999.450500488281,2,39.995735168457,10,21.9999998807907,1.8879591152654E-005,-6.21882963969256E-006,-1.40689426189056E-005,5.58336914480151E-008,0,0,0,0.0592236258089542,0.606484293937683,59280,0,0,0,0,0,0,0,0,0,0,0,0,0,0,0,0,0,0
,3956014435.73515,0,2,0,111.5353735,999.450500488281,2,39.995735168457,10,21.9999998807907,1.80169190571178E-005,-5.79737297812244E-006,-9.33568207983626E-006,-1.07134019344812E-005,0,0,0,0.0700040459632873,0.616234719753265,61440,0,0,0,0,0,0,0,0,0,0,0,0,0,0,0,0,0,0
,3956014561.85084,0,2,0,119.2792285,999.450500488281,2,39.995735168457,10,21.9999998807907,1.69903978530783E-005,-5.25553559782566E-006,4.06023627874674E-006,-1.27950270325528E-005,0,0,0,0.0431216657161713,0.641812443733215,59280,0,0,0,0,0,0,0,0,0,0,0,0,0,0,0,0,0,0
,3956014683.92047,0,2,0,126.9905625,999.450500488281,2,39.995735168457,10,21.9999998807907,1.61162115546176E-005,-5.10145309817744E-006,1.17282443170552E-005,-4.89046669827076E-006,0,0,0,0.0434649921953678,0.604630291461945,61440,0,0,0,0,0,0,0,0,0,0,0,0,0,0,0,0,0,0
,3956014804.70797,0,2,0,134.705612,999.450500488281,2,39.995735168457,10,21.9999998807907,1.51193935380434E-005,-4.75192837257055E-006,1.10340133687714E-005,6.94345180818345E-006,0,0,0,0.0545200705528259,0.662411987781525,61520,0,0,0,0,0,0,0,0,0,0,0,0,0,0,0,0,0,0
,3956014928.01495,0,2,0,142.6537475,999.450500488281,2,39.995735168457,10,21.9999998807907,1.43135575854103E-005,-4.58543354397989E-006,2.61943637269724E-006,1.35063119159895E-005,0,0,0,0.046177264302969,0.663853943347931,61520,0,0,0,0,0,0,0,0,0,0,0,0,0,0,0,0,0,0
,3956015048.09824,0,2,0,150.477089,999.450500488281,2,39.995735168457,10,21.9999998807907,1.35015861815191E-005,-4.30270711149205E-006,-7.80685149948113E-006,1.15534567157738E-005,0,0,0,0.0567860156297684,0.719369649887085,61520,0,0,0,0,0,0,0,0,0,0,0,0,0,0,0,0,0,0
,3956015170.33663,0,2,0,158.5000075,999.450500488281,2,39.995735168457,10,21.9999998807907,1.28979418150266E-005,-4.16287639382062E-006,-1.28318843053421E-005,2.61587047134526E-006,0,0,0,0.046451922506094,0.695439875125885,61440,0,0,0,0,0,0,0,0,0,0,0,0,0,0,0,0,0,0
,3956015295.01307,0,2,0,166.782219,999.450500488281,2,39.995735168457,10,21.9999998807907,1.2558865819301E-005,-3.99119517169311E-006,-1.02201529443846E-005,-8.6649661170668E-006,0,0,0,0.0422290191054344,0.695920526981354,59280,0,0,0,0,0,0,0,0,0,0,0,0,0,0,0,0,0,0
,3956015417.49447,0,2,0,174.8853915,999.450500488281,2,39.995735168457,10,21.9999998807907,1.1765743693104E-005,-3.83405449611018E-006,-6.80778782680136E-007,-1.14732383735827E-005,0,0,0,0.0522884540259838,0.5925452709198,59280,0,0,0,0,0,0,0,0,0,0,0,0,0,0,0,0,0,0
,3956015543.62118,0,2,0,183.3167725,999.450500488281,2,39.995735168457,10,21.9999998807907,1.14207987280679E-005,-3.59921295967069E-006,9.08228139451239E-006,-6.39563859294867E-006,0,0,0,0.0556530430912972,0.537441551685333,61440,0,0,0,0,0,0,0,0,0,0,0,0,0,0,0,0,0,0
,3956015668.16285,0,2,0,191.725937,999.450500488281,2,39.995735168457,10,21.9999998807907,1.10648024929105E-005,-3.51220910488337E-006,1.12749848995009E-005,4.02258092435659E-006,0,0,0,0.0396884121000767,0.710237205028534,61520,0,0,0,0,0,0,0,0,0,0,0,0,0,0,0,0,0,0
,3956015789.98304,0,2,0,199.9606325,999.450500488281,2,39.995735168457,10,21.9999998807907,1.04419195849914E-005,-2.99283942695183E-006,3.51933294950868E-006,1.15699467642116E-005,0,0,0,0.0718580037355423,0.536651909351349,61440,0,0,0,0,0,0,0,0,0,0,0,0,0,0,0,0,0,0
,3956015912.99342,0,2,0,208.2587355,999.450500488281,2,39.995735168457,10,21.9999998807907,1.02421317933477E-005,-3.16710270453768E-006,-5.37061123395688E-006,1.10223027149914E-005,0,0,0,0.0567516833543777,0.62035459280014,61440,0,0,0,0,0,0,0,0,0,0,0,0,0,0,0,0,0,0
,3956016032.55486,0,2,0,216.389557,999.450500488281,2,39.995735168457,10,21.9999998807907,9.66412153502461E-006,-2.91528749585268E-006,-1.11515746539226E-005,3.77813057639287E-006,0,0,0,0.0698323845863342,0.653828859329224,61440,0,0,0,0,0,0,0,0,0,0,0,0,0,0,0,0,0,0
,3956016153.01013,0,2,0,224.5719375,999.450500488281,2,39.995735168457,10,21.9999998807907,9.4169608928496E-006,-2.93994958155963E-006,-1.07688729258371E-005,-5.68710447623744E-006,0,0,0,0.0601162724196911,0.633400976657867,59280,0,0,0,0,0,0,0,0,0,0,0,0,0,0,0,0,0,0
,3956016273.94762,0,2,0,232.771797,999.450500488281,2,39.995735168457,10,21.9999998807907,8.97950576472795E-006,-3.05927596855327E-006,-3.81992231268669E-006,-1.10277778730961E-005,0,0,0,0.0406497232615948,0.608338236808777,61520,0,0,0,0,0,0,0,0,0,0,0,0,0,0,0,0,0,0
,3956016395.12573,0,2,0,241.05101,999.450500488281,2,39.995735168457,10,21.9999998807907,8.95128323463723E-006,-2.87104899143742E-006,6.98531766829546E-006,-9.54159531829646E-006,0,0,0,0.0455249436199665,0.676934659481049,61520,0,0,0,0,0,0,0,0,0,0,0,0,0,0,0,0,0,0
,3956016517.84324,0,2,0,249.337585,999.450500488281,2,39.995735168457,10,21.9999998807907,8.50639480631799E-006,-2.73945079243276E-006,1.2444158528524E-005,-3.66059737189062E-007,0,0,0,0.0758062452077866,0.727815449237823,61440,0,0,0,0,0,0,0,0,0,0,0,0,0,0,0,0,0,0
,3956016641.59383,0,2,0,257.843292,999.450500488281,2,39.995735168457,10,21.9999998807907,8.19680371932918E-006,-2.57868396147387E-006,7.58708665671293E-006,9.80148706730688E-006,0,0,0,0.0633092001080513,0.700246453285217,59280,0,0,0,0,0,0,0,0,0,0,0,0,0,0,0,0,0,0
,3956016766.56473,0,2,0,266.353073,999.450500488281,2,39.995735168457,10,21.9999998807907,8.18925309431506E-006,-2.65763469542435E-006,-2.08930828193843E-006,1.29504242067924E-005,0,0,0,0.0504688285291195,0.676934659481049,61440,0,0,0,0,0,0,0,0,0,0,0,0,0,0,0,0,0,0
,3956016884.17348,0,2,0,274.3092805,999.450500488281,2,39.995735168457,10,21.9999998807907,7.61766841606004E-006,-2.64273671746196E-006,-7.94707739260048E-006,6.72005717206048E-006,0,0,0,0.0447696298360825,0.729944050312042,61520,0,0,0,0,0,0,0,0,0,0,0,0,0,0,0,0,0,0
,3956016999.47482,0,2,0,281.4219055,999.450500488281,2,39.995735168457,10,21.9999998807907,7.831667062419E-006,-2.63033530245593E-006,-1.13397409222671E-005,-8.00875568529591E-007,0,0,0,0.0424693487584591,0.699697136878967,59280,0,0,0,0,0,0,0,0,0,0,0,0,0,0,0,0,0,0
,3956017114.50289,0,2,0,287.474457,999.450500488281,2,39.995735168457,10,21.9999998807907,7.29668727217359E-006,-2.30644673138158E-006,-5.65498430660227E-006,-6.66771029500524E-006,0,0,0,0.0485118739306927,0.701860070228577,61440,0,0,0,0,0,0,0,0,0,0,0,0,0,0,0,0,0,0
,3956017229.4947,0,2,0,292.501816,999.450500488281,2,39.995735168457,10,21.9999998807907,7.30554074834799E-006,-2.22983430830936E-006,1.79739436134696E-006,-6.30354861641535E-006,0,0,0,0.0647168308496475,0.704160332679748,59280,0,0,0,0,0,0,0,0,0,0,0,0,0,0,0,0,0,0
,3956017350.47632,0,2,0,296.715027,999.450500488281,2,39.995735168457,10,21.9999998807907,7.21562764738337E-006,-2.50054722528148E-006,5.81393078391557E-006,-3.55319525624509E-006,0,0,0,0.0477565601468086,1.03234505653381,61520,0,0,0,0,0,0,0,0,0,0,0,0,0,0,0,0,0,0
,3956017483.61414,0,2,0,299.430588,999.450500488281,2,39.995735168457,10,21.9999998807907,7.1288704930339E-006,-2.23615529648669E-006,5.40532118975534E-006,3.90157629226451E-006,0,0,0,0.0275690276175737,1.094486951828,61520,0,0,0,0,0,0,0,0,0,0,0,0,0,0,0,0,0,0
,3956017603.67297,0,2,0,300.1842495,999.450500488281,2,39.995735168457,10,21.9999998807907,7.0348646659113E-006,-2.30631189879205E-006,8.35482296679402E-007,7.64445394452196E-006,0,0,0,0.0453189499676228,0.425071150064468,59280,0,0,0,0,0,0,0,0,0,0,0,0,0,0,0,0,0,0
,3956017710.46013,0,2,0,300.3569335,999.450500488281,2,39.995735168457,10,21.9999998807907,7.10616177457268E-006,-2.18749664782081E-006,-3.67696270586748E-006,5.4180482038646E-006,0,0,0,0.044906958937645,0.473342686891556,59280,0,0,0,0,0,0,0,0,0,0,0,0,0,0,0,0,0,0